Workbook

Sheet Semana 1 -  03.02 a.07.02
B3: SEMANA 03 DE FEVEREIRO DE 2026 A 07 DE FEVEREIRO DE 2026
B8: MILHAGEM | C8: 62108.1 | D8: Milhas
N10: MILHAGEM DO CARRO NA SAIDA | Q10: 67327.1
M13: Estado | N13: Posto | O13: Valor | P13: Galão | Q13: $ / Galão | R13: Foto da milhagem do carro do abastecimento seguinte | S13: Milhas Rodada entre um foto e outro do abastecimento | T13: Milha/Galão
B14: MODELO DO CARRO | C14: PICK UP | D14: DELIVERED | E14: VALOR | F14: FORMA DE PG | G14: PRAZO (BD) | H14: DATA PG | J14: STATUS | L14: Abast 01 | M14: FLORIDA | N14: LOVES | O14: 141.44 | P14: 38 | Q14: =O14/P14 -> 3.7221053 | R14: 67733.3 | S14: =R14-Q10 -> 406.2 | T14: =S14/P14 -> 10.689474
B15: TESLA | C15: 46056 | D15: 46057 | E15: 245 | F15: SUPERPAY | G15: 5 | H15: 46064 | J15: PAGO | L15: Abast 02 | M15: GEORGIA | N15: CIRCLE K | O15: 100 | P15: 30.31 | Q15: =O15/P15 -> 3.2992412 | R15: 68026.1 | S15: =R15-R14 -> 292.8 | T15: =S15/P15 -> 9.6601782
B16: SPORTAGE | C16: 46056 | D16: 46057 | E16: 300 | F16: Check on delivery | G16: - | H16: 46057 | J16: PAGO | L16: Abast 03 | M16: CAROLINA DO SUL | N16: PILOT | O16: 160.76 | P16: 46.09 | Q16: =O16/P16 -> 3.4879583 | U16: Esqueceu da foto da milhagem
B17: FORD CARGO | C17: 46056 | D17: 46058 | E17: 650 | F17: Check on delivery | G17: - | H17: 46058 | J17: PAGO | L17: Abast 04 (T. EXT) | M17: VIRGINIA | N17: PILOT | O17: 228.75 | P17: 60.96 | Q17: =O17/P17 -> 3.7524606 | R17: 68633.4 | S17: =R17-R15 -> 607.3 | T17: =S17/P17 -> 9.9622703 | Z17: CARRO | AA17: MÊS | AB17: SEMANA | AC17: ESTADO PICK UP | AD17: PICK UP | AE17: ESTADO DELIVERY | AF17: DELIVERY | AG17: MILHAS | AH17: VALOR | AI17: $/MILHAS | AJ17: FORMA PG.
B18: PORSCHE | C18: 46057 | D18: 46059 | E18: 850 | F18: Superpay | G18: 3 | H18: =WORKDAY(D18,G18) -> 46064 | J18: PAGO | L18: Abast 06 (T.EXT) | M18: NEW JERSEY | N18: TA | O18: 223.12 | P18: 60.95 | Q18: =O18/P18 -> 3.6607055 | R18: 69318.4 | S18: =R18-R17 -> 685 | T18: =S18/P18 -> 11.23872 | Z18: TESLA | AA18: 46054 | AB18: SEMANA1 | AC18: FL | AD18: 1208 Pine Ave, Orlando, FL 32824, EUA | AE18: FL | AF18: 2412 W Tennessee St, Tallahassee, FL 32304, EUA | AG18: 272 | AH18: 212.5 | AI18: =AH18/AG18 -> 0.78125 | AJ18: PRAZO
B19: HONDA CRV | C19: 46057 | D19: 46058 | E19: 600 | F19: CASH | G19: - | H19: 46059 | J19: PAGO | L19: Abast 06 | Z19: SPORTAGE | AA19: 46054 | AB19: SEMANA1 | AC19: FL | AD19: 11801 W Colonial Dr, Ocoee, FL 34761, EUA | AE19: GA | AF19: Albany Auto Auction, 1421 Liberty Expy, Albany, GA 31705, Estados Unidos | AG19: 280 | AH19: 300 | AI19: =AH19/AG19 -> 1.0714286 | AJ19: CASH
B20: NISSA | C20: 46058 | D20: 46059 | E20: 250 | F20: Superpay | G20: 3 | H20: =WORKDAY(D20,G20) -> 46064 | J20: PENDENTE | L20: Abast 07 | Z20: FORD CARGO | AA20: 46054 | AB20: SEMANA1 | AC20: FL | AD20: ADESA Orlando, 2851 St Johns Pkwy, Sanford, FL 32771, EUA | AE20: VA | AF20: 8511 Manassas Dr, Manassas Park, VA 20111, EUA | AG20: 817 | AH20: 650 | AI20: =AH20/AG20 -> 0.79559364 | AJ20: CASH
B21: TAHONE | C21: 46059 | D21: 46062 | E21: 700 | F21: CASH | G21: - | H21: 46062 | J21: PAGO | L21: Abast 08 | Z21: PORSCHE | AA21: 46054 | AB21: SEMANA1 | AC21: FL | AD21: 1825 Commerce Blvd, Midway, FL 32343, EUA | AE21: NJ | AF21: 1700 W Blancke St, Linden, NJ 07036, EUA | AG21: 1087 | AH21: 850 | AI21: =AH21/AG21 -> 0.78196872 | AJ21: PRAZO
B22: RAV4 | C22: 46060 | D22: 46062 | E22: 550 | F22: Zelle | G22: - | H22: 46062 | J22: PAGO | L22: Abast 05 (DEF) | M22: MARYLAND | N22: TA | O22: 23.2 | P22: 4.74 | Q22: =O22/P22 -> 4.8945148 | Z22: HONDA CRV | AA22: 46054 | AB22: SEMANA1 | AC22: GA | AD22: 368 Oakridge Church Rd.Tifton, GA 31794 | AE22: PA | AF22: 1117 N Godfrey St, Allentown, PA 18109, EUA | AG22: 952 | AH22: 600 | AI22: =AH22/AG22 -> 0.6302521 | AJ22: CASH
L23: Abast 10 | Z23: NISSAN | AA23: 46054 | AB23: SEMANA1 | AC23: VA | AD23: 17489 Old Stage Coach Rd, Dumfries, VA 22026 | AE23: NJ | AF23: 666 hwy 1&9 , Elizabeth, NJ 07202 | AG23: 241 | AH23: 250 | AI23: =AH23/AG23 -> 1.0373444 | AJ23: PRAZO
O24: =SUM(O14:O23) -> 877.27 | Z24: TAHOE | AA24: 46054 | AB24: SEMANA1 | AC24: NJ | AD24: 125 W Main St, Somerville, NJ 08876 Somerville, NJ 08876 | AE24: FL | AF24: 52 Dade ct. Saint Augustine Florida. 32092 Saint Augustine, FL 32092 | AG24: 942 | AH24: 700 | AI24: =AH24/AG24 -> 0.74309979 | AJ24: CASH
E25: =SUM(E15:E24) -> 4145 | Z25: RAV4 | AA25: 46054 | AB25: SEMANA1 | AC25: NJ | AD25: WEST ORANGE , NJ 07052 | AE25: FL | AF25: JACKSONVILLE, FL 32099 | AG25: 934 | AH25: 550 | AI25: =AH25/AG25 -> 0.5888651 | AJ25: CASH
B26: DIA 03.02 - MARCOS PEGOU O CARRO NO YARD PELA MANHA. E FOI EM CASA PARA ALMOÇAR PEGAR AS COISAS E SAIR. "SAIU" UMAS 14HRS | M26: MEDIA DO PREÇO DO GALÃO | P26: =SUM(O14:O21)/SUM(P14:P21) -> 3.6141932 | Q26: =P26/P28 -1 -> 0.095210067
B27: DIA 03.02 - ERA PARA PEGAR 2 TESLS, SOMENTE 1 FICOU PRONTO E ACABOU QUE FICOU ESPERANDO UM POUCO LA
B28: DIA 06.02 - CHEGAMOS PARA PEGAR UM CARRO E JÁ TINHAM PEGUE , ISSO NA SEXTA A NOITE E FICAMOS A NOITE PARADA. E PERDEMOS A VAN DO DIA SEGUINTE | M28: META | P28: 3.3 | AH28: MEDIA | AI28: =SUM(AH18:AH27)/SUM(AG18:AG27) -> 0.74434389
B29: DIA 07.02 - SUBINDO 2H PARA PEGAR 2 CAARROS PARA DESCER PARA A FLORIDA , ESSE CARROS FORAM CANCELADOS. DESCEMOS 3H PARA PEGAR A VAN A MESMA JÁ TINHA SIDO PEQGUE
B30: DIA 07 EXTRAMEENTE ESTRESSANTE E DESORGANIZADO POR PARTE DA EQUIPE DO RODIRGO.
N31: MILHAGEM DO CARRO NoO FIM | Q31: 69703.6 | R31: NÃO PEGAMOS O RELA - PEGAMOS APÓS O ABASTECIMENTO NO DOMINGO AS 15:33
C34: SEMANA | D34: PERCENTUAL | E34: VALOR
B35: PRESTAÇÃO DE CONTAS RODRIGO | C35: =E25 -> 4145 | D35: 0.12 | E35: =C35*D35 -> 497.4
B36: DRIVER (MARCOS) | C36: =E25 -> 4145 | D36: 0.3 | E36: =C36*D36 -> 1243.5 | H36: Carro pagos diretos ao Rodrigo | K36: =E15+E18+E20 -> 1345
H37: Prestação de contas Rodrigo Semana | K37: =E35 -> 497.4
H38: Prestação de contas Rodrigo SEGURO | K38: =C44 -> 250
H39: Prestação de contas Rodrigo Superdispatcher | K39: 50
B40: GASTOS | C40: VALOR | I40: Saldo a Receber | K40: =K37+K38+K39-K36 -> -547.6
B41: DISPATCHER (RODRIGO) | C41: =E35 -> 497.4 | D41: - | E41: =C41/$E$25 -> 0.12 | H41: Falta Receber da Nissan | K41: 250 | L41: PENDENTE
B42: DRIVER (MARCOS) | C42: =E36 -> 1243.5 | D42: - | E42: =C42/$E$25 -> 0.3 | K42: =K40+K41 -> -297.6 | L42: PAGO
B43: COMBUSTIVEL | C43: =O24 -> 877.27 | D43: - | E43: =C43/$E$25 -> 0.21164536
B44: SEGURO CARGA SEMANAL | C44: 250 | D44: - | E44: =C44/$E$25 -> 0.060313631
B45: SUPERDISPATCHER (50 O MÊS) | D45: =50/4 -> 12.5 | E45: =D45/$E$25 -> 0.0030156815 | G45: Marcos Prestação de Contas | K45: =E36 -> 1243.5
B46: LOG BOOK MAGICA (153 O MÊS) | C46: - | D46: =153/4 -> 38.25 | E46: =D46/$E$25 -> 0.0092279855 | G46: Debito do abastecimento que o Samuca pagou | K46: -30
B47: YARD (150 O MÊS) | C47: - | D47: =150/4 -> 37.5 | E47: =D47/$E$25 -> 0.0090470446 | G47: Abasteceu o DEF no domingo dia 08 | K47: 20
B48: SEGURO DO CARRO (183 O MÊS) | C48: - | D48: =183/4 -> 45.75 | E48: =D48/$E$25 -> 0.011037394 | G48: Comprou o teste do fusivel | K48: 10 | P48: MILHAGEM DO CARRO NA SAIDA | S48: 67327.1
B49: FINANCIAMENTO CARRO (1197,66 O MÊS) | C49: - | D49: =1197.66/4 -> 299.415 | E49: =D49/$E$25 -> 0.072235223 | G49: Debito CASH recebimento honda civiq | K49: -600 | P49: MILHAGEM DO CARRO NoO FIM | S49: 69703.6
B50: PEDAGIOS | C50: - | D50: 100 | E50: =D50/$E$25 -> 0.024125452 | I50: Saldo a Receber | K50: =K45+K49+K46+K47+K48 -> 643.5 | L50: PAGO | S50: =S49-S48 -> 2376.5 | T50: milhas
B51: MANUTENÇÃO | C51: - | D51: 100 | E51: =D51/$E$25 -> 0.024125452 | S51: =E25 -> 4145 | T51: produção semana
...

Sheet Semana 2 -  08.02 a 14.02
B3: SEMANA 03 DE FEVEREIRO DE 2026 A 07 DE FEVEREIRO DE 2026
B8: MILHAGEM | C8: 62108.1 | D8: Milhas
N10: MILHAGEM DO CARRO NA SAIDA | Q10: 69318.4 | R10: FOI CONSIDERADO AQUI O ABASTECIMENTO 6 DA SEMANA PASSADA
M13: Estado | N13: Posto | O13: Valor | P13: Galão | Q13: $ / Galão | R13: Foto da milhagem do carro do abastecimento seguinte | S13: Milhas Rodada entre um foto e outro do abastecimento | T13: Milha/Galão
B14: MODELO DO CARRO | C14: PICK UP | D14: DELIVERED | E14: VALOR | F14: FORMA DE PG | G14: PRAZO (BD) | H14: DATA PG | J14: STATUS | L14: Abast 01 | M14: MAYRALND | N14: TA | O14: 72.07 | P14: 20.14 | Q14: =O14/P14 -> 3.5784508 | R14: 69703.6 | S14: =R14-Q10 -> 385.2 | T14: =S14/P14 -> 19.126117
B15: VAN | C15: 46061 | D15: 46062 | E15: 700 | F15: Zelle | G15: - | H15: 46062 | J15: PAGO | L15: Abast 02 | M15: VIRGINA | N15: TA | O15: 255.54 | P15: 76.64 | Q15: =O15/P15 -> 3.3342902 | S15: =R15-Q11 -> 0 | T15: =S15/P15 -> 0 | U15: ESQUECEU DE BATER A FOTO
B16: ATLAS | C16: 46063 | D16: 46064 | E16: 500 | F16: Superpay | G16: 5 | H16: =WORKDAY(D16,G16) -> 46071 | J16: PENDENTE | L16: Abast 04 | M16: FLORIDA | N16: TA | O16: 287.35 | P16: 85.91 | Q16: =O16/P16 -> 3.3447794 | R16: 70572.8 | S16: =R16-R14 -> 869.2 | T16: =S16/(P16+P15) -> 5.3472778
B17: HONDA | C17: 46063 | D17: 46064 | E17: 325 | F17: Cash | G17: - | H17: 46064 | J17: PAGO | L17: Abast 05 (T. EXT) | M17: CAROLINA DO SUL | N17: TA | O17: 300.38 | P17: 88.96 | Q17: =O17/P17 -> 3.3765737 | R17: 71491.1 | S17: =R17-R16 -> 918.3 | T17: =S17/(P17+P16) -> 5.2513296 | AC17: CARRO | AD17: MÊS | AE17: SEMANA | AF17: ESTADO PICK UP | AG17: PICK UP | AH17: ESTADO DELIVERY | AI17: DELIVERY | AJ17: MILHAS | AK17: VALOR | AL17: $/MILHAS | AM17: FORMA PG.
B18: JEEP WRANGLER | C18: 46063 | D18: 46065 | E18: 600 | F18: Superpay | G18: 5 | H18: =WORKDAY(D18,G18) -> 46072 | J18: PENDENTE | L18: Abast 06 (T.EXT) | M18: VIRGINIA | N18: TA | O18: 279.8 | P18: 83.15 | Q18: =O18/P18 -> 3.365003 | R18: 72312.4 | S18: =R18-R17 -> 821.3 | T18: =S18/(P18+P17) -> 4.7719482 | AC18: VAN | AD18: 46054 | AE18: SEMANA 2 | AF18: MD | AG18: 11550 Crossroads Cir, Baltimore, MD 21220, EUA | AH18: FL | AI18: 2412 W Tennessee St, Tallahassee, FL 32304, EUA | AJ18: 963 | AK18: 700 | AL18: =AK18/AJ18 -> 0.72689512 | AM18: CASH
B19: F150 | C19: 46064 | D19: 46065 | E19: 350 | F19: CH para 10 dias | G19: 10 | H19: =WORKDAY(D19,G19) -> 46079 | J19: PENDENTE | L19: Abast 07 | O19: =21+275 -> 296 | P19: =77+4.8 -> 81.8 | AC19: ATLAS | AD19: 46054 | AE19: SEMANA 2 | AF19: FL | AG19: 925 bartow rd Lakeland, FL 33801 | AH19: NC | AI19: Albany Auto Auction, 1421 Liberty Expy, Albany, GA 31705, Estados Unidos | AJ19: 678 | AK19: 500 | AL19: =AK19/AJ19 -> 0.73746313 | AM19: PRAZO
B20: ELENTRAN | C20: 46065 | D20: 46067 | E20: 650 | F20: CHEK | G20: - | H20: 46067 | J20: PAGO | AC20: HONDA | AD20: 46054 | AE20: SEMANA 2 | AF20: FL | AG20: 11801 west colonial dr. Ocoee, FL 34761 | AH20: SC | AI20: 8511 Manassas Dr, Manassas Park, VA 20111, EUA | AJ20: 494 | AK20: 325 | AL20: =AK20/AJ20 -> 0.65789474 | AM20: CASH
B21: LEXUS 2016 | C21: 46065 | D21: 46067 | E21: 550 | F21: CHEK | G21: - | H21: 46067 | J21: PAGO | AC21: JEEP | AD21: 46054 | AE21: SEMANA 2 | AF21: FL | AG21: 9800 BACHMAN ROAD ORLANDO, FL 32824 | AH21: VA | AI21: 1700 W Blancke St, Linden, NJ 07036, EUA | AJ21: 724 | AK21: 600 | AL21: =AK21/AJ21 -> 0.82872928 | AM21: PRAZO
B22: LEXUS | C22: 46065 | D22: 46066 | E22: 450 | F22: Cash | G22: - | H22: 46066 | J22: PAGO | L22: Abast 03 (DEF) | M22: CAROLINA DO SUL | N22: TA | O22: 20 | P22: =O22/Q22 -> 4.6620047 | Q22: 4.29 | U22: FOI PAGO COM O DINHEITO DOMARCOS - FEITO NA PRESTAÇÃO DE CONTA DA SEMANA PASSADA | AC22: F150 | AD22: 46054 | AE22: SEMANA 2 | AF22: SC | AG22: 431 Hospitality Ln Myrtle Beach, SC 29579 | AH22: VA | AI22: 1117 N Godfrey St, Allentown, PA 18109, EUA | AJ22: 301 | AK22: 350 | AL22: =AK22/AJ22 -> 1.1627907 | AM22: PRAZO
B23: SILVERADO | C23: 46067 | D23: 46069 | E23: 700 | F23: Cash | G23: - | H23: 46070 | J23: PAGO | L23: Abast 10 | AC23: ELENTRAN | AD23: 46054 | AE23: SEMANA 2 | AF23: VA | AG23: 15100 woods edge road south Chesterfield, VA 23834 | AH23: AL | AI23: 666 hwy 1&9 , Elizabeth, NJ 07202 | AJ23: 670 | AK23: 650 | AL23: =AK23/AJ23 -> 0.97014925 | AM23: CASH
O24: =SUM(O14:O22) -> 1511.14 | AC24: LEXUS 2016 | AD24: 46054 | AE24: SEMANA 2 | AF24: VA | AG24: 3902 Richmond Hwy, Stafford, VA 22554 | AH24: AL | AI24: 52 Dade ct. Saint Augustine Florida. 32092 | AJ24: 715 | AK24: 550 | AL24: =AK24/AJ24 -> 0.76923077 | AM24: CASH
E25: =SUM(E15:E24) -> 4825 | AC25: LEXUS | AD25: 46054 | AE25: SEMANA 2 | AF25: VA | AG25: 15201 Review Road Culpeper, VA 22701 | AH25: GA | AI25: 4349 abbots bridge rdDuluth, GA 30097 | AJ25: 536 | AK25: 450 | AL25: =AK25/AJ25 -> 0.83955224 | AM25: CASH
M26: MEDIA DO PREÇO DO GALÃO | P26: =SUM(O14:O21)/SUM(P14:P21) -> 3.4153459 | Q26: =P26/P28 -1 -> 0.034953289 | AC26: SILVERADO | AD26: 46054 | AE26: SEMANA 2 | AF26: AL | AG26: 2285 County Road 51N Camden, AL 36726 | AH26: NC | AI26: 175 Freedom Way Jacksonville, NC 28544 | AJ26: 692 | AK26: 700 | AL26: =AK26/AJ26 -> 1.0115607 | AM26: CASH
M28: META | P28: 3.3 | AK28: MEDIA | AL28: =SUM(AK18:AK27)/SUM(AJ18:AJ27) -> 0.83578729
P30: AINDA NÃO CHEGOU O VALOR DO COMBUSTIVER POR EMAIL
B31: DIA 08.02 - DOMINGO - PEGAMOS 1 VAN PARA TAMPA - CARRO JÁ ESTAVA COM OUTROS 2 CARROS DA SEMANA PASSADA
B32: DIA 09.02 - SEGUNDA - ENTREGA RAV4 , ENTREGA TAHOE E ENTREGA VAN - DIA TODO - TIVEMOS UM SIERRA CANCELADO E DOIS CIBERTRUCK - PREÇOS BONS
B33: DIA 09.02 - AINDA TEVE QUE VOLTAR A BASE BATENDO - PARA CONCERTAR TRAILER - AJEITAR A PARTE DAS LUZES
B34: DIA 10.02 - OCARRO PASSOU A MANHA TODA NA OFICINA PARA CONCERTAR UM APARTE ELETRICA DO TRAILER. SO SAIU A TARDE
B37: DIA 14.02 - DE NOVO FICAMOS SEM ATENDIMENTO DO RODRIGO NO SABADO - SOMENTE 1 CARRO - DE NOVO ESTRESS
C39: SEMANA | D39: PERCENTUAL | E39: VALOR
B40: PRESTAÇÃO DE CONTAS RODRIGO | C40: =E25 -> 4825 | D40: 0.12 | E40: =C40*D40 -> 579
B41: DRIVER (MARCOS) | C41: =E25 -> 4825 | D41: 0.3 | E41: =C41*D41 -> 1447.5 | G41: PRESTAÇÃO DE CONTAS DISPATCHER - 08.02 a 14.02
G42: Prestação de contas Rodrigo (12%) Semana | K42: =E40 -> 579
G43: Carro pagos diretos ao Rodrigo (Atlas, Jeep, F150) | K43: =E16+E18+E19 -> 1450
G44: Valro SEGURO semanal | K44: =C49 -> 250
B45: GASTOS | C45: VALOR | G45: Valor a pagar BROOKFREE - LEXUS 2016 | K45: 50
B46: DISPATCHER (RODRIGO) | C46: =E40 -> 579 | D46: - | E46: =C46/$E$25 -> 0.12 | I46: Saldo a Receber do Rodrigo | K46: =K43-K42-K44-K45 -> 571 | L46: PENDENTE
B47: DRIVER (MARCOS) | C47: =E41 -> 1447.5 | D47: - | E47: =C47/$E$25 -> 0.3 | G47: Semana 01.02 a 08.02 Pendente valor NISSAN | K47: 250
B48: COMBUSTIVEL | C48: =O24 -> 1511.14 | D48: - | E48: =C48/$E$25 -> 0.31318964 | K48: =K46+K47 -> 821
B49: SEGURO CARGA SEMANAL | C49: 250 | D49: - | E49: =C49/$E$25 -> 0.051813472
B50: SUPERDISPATCHER (50 O MÊS) | D50: =50/4 -> 12.5 | E50: =D50/$E$25 -> 0.0025906736
B51: LOG BOOK MAGICA (153 O MÊS) | C51: - | D51: =153/4 -> 38.25 | E51: =D51/$E$25 -> 0.0079274611
B52: YARD (150 O MÊS) | C52: - | D52: =150/4 -> 37.5 | E52: =D52/$E$25 -> 0.0077720207 | G52: PRESTAÇÃO DE CONTAS DRIVER 08.02 a 14.02
B53: SEGURO DO CARRO (183 O MÊS) | C53: - | D53: =183/4 -> 45.75 | E53: =D53/$E$25 -> 0.0094818653 | G53: Marcos Prestação de Contas | K53: =E41 -> 1447.5
B54: FINANCIAMENTO CARRO (1197,66 O MÊS) | C54: - | D54: =1197.66/4 -> 299.415 | E54: =D54/$E$25 -> 0.062054922
...

Sheet Semana 3 -  15.02 a 21.02 
B3: SEMANA 03 DE FEVEREIRO DE 2026 A 07 DE FEVEREIRO DE 2026
B8: MILHAGEM | C8: 62108.1 | D8: Milhas
N10: MILHAGEM DO CARRO NA SAIDA | Q10: 69318.4 | R10: FOI CONSIDERADO AQUI O ABASTECIMENTO 6 DA SEMANA PASSADA
M13: Estado | N13: Posto | O13: Valor | P13: Galão | Q13: $ / Galão | R13: Foto da milhagem do carro do abastecimento seguinte | S13: Milhas Rodada entre um foto e outro do abastecimento | T13: Milha/Galão
B14: MODELO DO CARRO | C14: PICK UP | D14: DELIVERED | E14: VALOR | F14: FORMA DE PG | G14: PRAZO (BD) | H14: DATA PG | J14: STATUS | L14: Abast 01 | M14: CAROLINA DO SUL | N14: TA | O14: 279.83 | P14: 87.4 | Q14: =O14/P14 -> 3.2017162 | R14: 73958.7
B15: NISSAN 2015 | C15: 46068 | D15: 46069 | E15: 400 | F15: CASH | G15: - | H15: 46069 | J15: PAGO | L15: Abast 02 | M15: NEW JERSEY | N15: TA | O15: 308.79 | P15: 84.82 | Q15: =O15/P15 -> 3.6405329 | R15: 74761 | S15: =R15-R14 -> 802.3 | T15: =S15/P15 -> 9.458854
B16: VAN | C16: 46069 | D16: 46070 | E16: 300 | F16: CHECK | G16: - | H16: 46070 | J16: PAGO | L16: Abast 04
B17: HONDA 2019 | C17: 46069 | D17: 46071 | E17: 500 | F17: CASH | G17: - | H17: 46071 | J17: PAGO | L17: Abast 05 (T. EXT) | AC17: CARRO | AD17: MÊS | AE17: SEMANA | AF17: ESTADO PICK UP | AG17: PICK UP | AH17: ESTADO DELIVERY | AI17: DELIVERY | AJ17: MILHAS | AK17: VALOR | AL17: $/MILHAS | AM17: FORMA PG.
B18: YOKON | C18: 46069 | D18: 46071 | E18: 450 | F18: CHECK | G18: - | H18: 46071 | J18: PAGO | L18: Abast 06 (T.EXT) | AC18: NISSA 2015 | AD18: 46054 | AE18: SEMANA 3 | AF18: AL | AG18: 2101 Grand Ave Birmingham, AL 35226 | AH18: NC | AI18: 6133 Saybrook Dr Raleigh, NC 27604 | AJ18: 566 | AK18: 400 | AL18: =AK18/AJ18 -> 0.70671378 | AM18: CASH
B19: JAGUAR | C19: 46070 | D19: 46071 | E19: 300 | F19: CHECK | G19: - | H19: 46071 | J19: PAGO | L19: Abast 07 | AC19: VAN | AD19: 46054 | AE19: SEMANA 3 | AF19: NC | AG19: 60 Sadisco Road Clayton, NC 27520 | AH19: VA | AI19: 125 falls run dr suite 113 Fredericksburg, VA 22406 | AJ19: 230 | AK19: 300 | AL19: =AK19/AJ19 -> 1.3043478 | AM19: CASH
B20: CHEVY C10 | C20: 46071 | E20: 850 | F20: CASH | AC20: HONDA 2019 | AD20: 46054 | AE20: SEMANA 3 | AF20: NC | AG20: 60 Sadisco Road Clayton, NC 27520 | AH20: MA | AI20: 205A Wildwood Avenue Worcester, MA 01603 | AJ20: 675 | AK20: 500 | AL20: =AK20/AJ20 -> 0.74074074 | AM20: CASH
B21: AUDI Q5 | C21: 46071 | E21: 600 | F21: CASH | AC21: YOKON | AD21: 46054 | AE21: SEMANA 3 | AF21: NC | AG21: 318 bagley rd kenly , NC 27542 | AH21: NJ | AI21: 447 Oakshade Road Shamong, NJ 08088 | AJ21: 419 | AK21: 450 | AL21: =AK21/AJ21 -> 1.0739857 | AM21: CASH
L22: Abast 03 (DEF) | AC22: JAGUAR | AD22: 46054 | AE22: SEMANA 3 | AF22: VA | AG22: 120 Auction Dr Fredericksburg, VA 22406 | AH22: PA | AI22: 1476 U.S. 209 Brodheadsville, PA 18322 | AJ22: 264 | AK22: 300 | AL22: =AK22/AJ22 -> 1.1363636 | AM22: CASH
L23: Abast 10 | AC23: CHEVY C10 | AD23: 46054 | AE23: SEMANA 3 | AF23: MA | AG23: 110 North Main Street Uxbridge, MA 01569 | AH23: SC | AI23: 1266 Cypress Shoal Drive Conway, SC 29526 | AJ23: 825 | AK23: 850 | AL23: =AK23/AJ23 -> 1.030303 | AM23: CASH
O24: =SUM(O14:O22) -> 588.62 | AC24: AUDI Q5 | AD24: 46054 | AE24: SEMANA 3 | AF24: MA | AG24: 518 Hazel Street Uxbridge, MA 01569 | AH24: VA | AI24: 3335 North Military Highway Norfolk, VA 23518 | AJ24: 544 | AK24: 600 | AL24: =AK24/AJ24 -> 1.1029412 | AM24: CASH
E25: =SUM(E15:E24) -> 3400
M26: MEDIA DO PREÇO DO GALÃO | P26: =SUM(O14:O21)/SUM(P14:P21) -> 3.4178376 | Q26: =P26/P28 -1 -> 0.035708379
M28: META | P28: 3.3 | AK28: MEDIA | AL28: =SUM(AK18:AK27)/SUM(AJ18:AJ27) -> 0.96508657
C39: SEMANA | D39: PERCENTUAL | E39: VALOR
B40: PRESTAÇÃO DE CONTAS RODRIGO | C40: =E25 -> 3400 | D40: 0.12 | E40: =C40*D40 -> 408
B41: DRIVER (MARCOS) | C41: =E25 -> 3400 | D41: 0.3 | E41: =C41*D41 -> 1020 | G41: PRESTAÇÃO DE CONTAS DISPATCHER - 08.02 a 14.02
G42: Prestação de contas Rodrigo (12%) Semana | K42: =E40 -> 408
G43: Carro pagos diretos ao Rodrigo () | K43: 0
G44: Valro SEGURO semanal | K44: =C49 -> 250
B45: GASTOS | C45: VALOR
B46: DISPATCHER (RODRIGO) | C46: =E40 -> 408 | D46: - | E46: =C46/$E$25 -> 0.12 | I46: Saldo a Receber do Rodrigo | K46: =K43-K42-K44-K45 -> -658
B47: DRIVER (MARCOS) | C47: =E41 -> 1020 | D47: - | E47: =C47/$E$25 -> 0.3
B48: COMBUSTIVEL | C48: =O24 -> 588.62 | D48: - | E48: =C48/$E$25 -> 0.17312353
B49: SEGURO CARGA SEMANAL | C49: 250 | D49: - | E49: =C49/$E$25 -> 0.073529412
B50: SUPERDISPATCHER (50 O MÊS) | D50: =50/4 -> 12.5 | E50: =D50/$E$25 -> 0.0036764706
B51: LOG BOOK MAGICA (153 O MÊS) | C51: - | D51: =153/4 -> 38.25 | E51: =D51/$E$25 -> 0.01125
B52: YARD (150 O MÊS) | C52: - | D52: =150/4 -> 37.5 | E52: =D52/$E$25 -> 0.011029412 | G52: PRESTAÇÃO DE CONTAS DRIVER 08.02 a 14.02
B53: SEGURO DO CARRO (183 O MÊS) | C53: - | D53: =183/4 -> 45.75 | E53: =D53/$E$25 -> 0.013455882 | G53: Marcos Prestação de Contas | K53: =E41 -> 1020
B54: FINANCIAMENTO CARRO (1197,66 O MÊS) | C54: - | D54: =1197.66/4 -> 299.415 | E54: =D54/$E$25 -> 0.088063235 | G54: Dinheiro com ele - NISSAN 2015 | K54: 400
B55: PEDAGIOS | C55: - | D55: 100 | E55: =D55/$E$25 -> 0.029411765 | I55: Saldo a Pagar Marcos | K55: =K53-K54 -> 620
B56: MANUTENÇÃO | C56: - | D56: 100 | E56: =D56/$E$25 -> 0.029411765
C58: =SUM(C46:C57) -> 2266.62 | D58: =SUM(D50:D57) -> 633.415 | E58: =SUM(E46:E57) -> 0.85295147
B59: TOTAL | C59: =C58+D58 -> 2900.035
B60: RESULTADO DA SEMANA | C60: =E25-C59 -> 499.965 | E60: =C60/E25 -> 0.14704853

Sheet EVOLUÇÃO
G10: FATURAMENTO | H10: VARIAÇÃO | I10: $/GALÃO | J10: VARIAÇÃO | K10: $/MILHA | L10: VARIAÇÃO | M10: GASTO COMB. | N10: VARIAÇÃO | O10: RESULTADO | P10: VARIAÇÃO
E11: SEMANA 1 | F11: 01.02.26 a 07.02.26 | G11: ='Semana 1 - 03.02 a.07.02'!E25 -> 4145 | H11: - | I11: ='Semana 1 - 03.02 a.07.02'!P26 -> 3.6141932 | J11: - | K11: ='Semana 1 - 03.02 a.07.02'!AI28 -> 0.74434389 | L11: - | M11: ='Semana 1 - 03.02 a.07.02'!O24 -> 877.27 | N11: - | O11: ='Semana 1 - 03.02 a.07.02'!C55 -> 643.415 | P11: -
E12: SEMANA 2 | F12: 08.02.26 a 14.02.26 | G12: ='Semana 2 - 08.02 a 14.02'!E25 -> 4825 | H12: =G12/G11-1 -> 0.16405308 | I12: ='Semana 2 - 08.02 a 14.02'!P26 -> 3.4153459 | J12: =I12/I11-1 -> -0.055018466 | K12: ='Semana 2 - 08.02 a 14.02'!AL28 -> 0.83578729 | L12: =K12/K11-1 -> 0.122851 | M12: ='Semana 2 - 08.02 a 14.02'!O24 -> 1511.14 | N12: =M12/M11-1 -> 0.72254836 | O12: ='Semana 2 - 08.02 a 14.02'!C60 -> 403.945 | P12: =O12/O11-1 -> -0.37218591
E13: SEMANA 3 | F13: 15.02.26 a 21.02.26 | H13: =G13/G12-1 -> -1 | J13: =I13/I12-1 -> -1 | L13: =K13/K12-1 -> -1 | N13: =M13/M12-1 -> -1 | P13: =O13/O12-1 -> -1

Sheet Resumo
C8: Faturado | D8: ='Semana 1 - 03.02 a.07.02'!E25+'Semana 2 - 08.02 a 14.02'!E25 -> 8970
C10: GASTOS | D10: VALOR
C11: DISPATCHER (RODRIGO) | D11: ='Semana 1 - 03.02 a.07.02'!C41+'Semana 2 - 08.02 a 14.02'!C46 -> 1076.4 | E11: - | F11: =D11/$D$8 -> 0.12
C12: DRIVER (MARCOS) | D12: ='Semana 1 - 03.02 a.07.02'!C42+'Semana 2 - 08.02 a 14.02'!C47 -> 2691 | E12: - | F12: =D12/$D$8 -> 0.3
C13: COMBUSTIVEL | D13: ='Semana 1 - 03.02 a.07.02'!C43+'Semana 2 - 08.02 a 14.02'!C48 -> 2388.41 | E13: - | F13: =D13/$D$8 -> 0.26626644
C14: SEGURO CARGA SEMANAL | D14: ='Semana 1 - 03.02 a.07.02'!C44+'Semana 2 - 08.02 a 14.02'!C49 -> 500 | E14: - | F14: =D14/$D$8 -> 0.05574136
C15: SUPERDISPATCHER (50 O MÊS) | E15: ='Semana 1 - 03.02 a.07.02'!D45+'Semana 2 - 08.02 a 14.02'!D50 -> 25 | F15: =E15/$D$8 -> 0.002787068
C16: LOG BOOK MAGICA (153 O MÊS) | D16: - | E16: ='Semana 1 - 03.02 a.07.02'!D46+'Semana 2 - 08.02 a 14.02'!D51 -> 76.5 | F16: =E16/$D$8 -> 0.0085284281
C17: YARD (150 O MÊS) | D17: - | E17: ='Semana 1 - 03.02 a.07.02'!D47+'Semana 2 - 08.02 a 14.02'!D52 -> 75 | F17: =E17/$D$8 -> 0.008361204
C18: SEGURO DO CARRO (183 O MÊS) | D18: - | E18: ='Semana 1 - 03.02 a.07.02'!D48+'Semana 2 - 08.02 a 14.02'!D53 -> 91.5 | F18: =E18/$D$8 -> 0.010200669
C19: FINANCIAMENTO CARRO (1197,66 O MÊS) | D19: - | E19: ='Semana 1 - 03.02 a.07.02'!D49+'Semana 2 - 08.02 a 14.02'!D54 -> 598.83 | F19: =E19/$D$8 -> 0.066759197
C20: PEDAGIOS | D20: - | E20: ='Semana 1 - 03.02 a.07.02'!D50+'Semana 2 - 08.02 a 14.02'!D55 -> 200 | F20: =E20/$D$8 -> 0.022296544
C21: MANUTENÇÃO | D21: - | E21: ='Semana 1 - 03.02 a.07.02'!D51+'Semana 2 - 08.02 a 14.02'!D56 -> 200 | F21: =E21/$D$8 -> 0.022296544
C22: IRON WAY | D22: =D8-D11-D12-D13-D14-E15-E16-E17-E18-E19-E20-E21 -> 1047.36 | F22: =D22/$D$8 -> 0.11676254
F24: =SUM(F11:F23) -> 1

Sheet SIMILAÇOES
C7: FATURAR NA SEMANA | D7: 4500 | H7: FATURAR NA SEMANA | I7: 5000
C9: GASTOS | D9: VALOR | H9: GASTOS | I9: VALOR
C10: DISPATCHER (RODRIGO) | D10: =D7*0.12 -> 540 | E10: - | F10: =D10/$D$7 -> 0.12 | H10: DISPATCHER (RODRIGO) | I10: =I7*0.12 -> 600 | J10: - | K10: =I10/$D$7 -> 0.13333333
C11: DRIVER (MARCOS) | D11: =D7*0.3 -> 1350 | E11: - | F11: =D11/$D$7 -> 0.3 | H11: DRIVER (MARCOS) | I11: =I7*0.3 -> 1500 | J11: - | K11: =I11/$D$7 -> 0.33333333
C12: COMBUSTIVEL | D12: 850 | E12: - | F12: =D12/$D$7 -> 0.18888889 | H12: COMBUSTIVEL | I12: 1100 | J12: - | K12: =I12/$D$7 -> 0.24444444
C13: SEGURO CARGA SEMANAL | D13: 250 | E13: - | F13: =D13/$D$7 -> 0.055555556 | H13: SEGURO CARGA SEMANAL | I13: 250 | J13: - | K13: =I13/$D$7 -> 0.055555556
C14: LOG BOOK MAGICA (153 O MÊS) | D14: - | E14: =153/4 -> 38.25 | F14: =E14/$D$7 -> 0.0085 | H14: LOG BOOK MAGICA (153 O MÊS) | I14: - | J14: =153/4 -> 38.25 | K14: =J14/$D$7 -> 0.0085
C15: YARD (150 O MÊS) | D15: - | E15: =150/4 -> 37.5 | F15: =E15/$D$7 -> 0.0083333333 | H15: YARD (150 O MÊS) | I15: - | J15: =150/4 -> 37.5 | K15: =J15/$D$7 -> 0.0083333333
C16: SEGURO DO CARRO (183 O MÊS) | D16: - | E16: =183/4 -> 45.75 | F16: =E16/$D$7 -> 0.010166667 | H16: SEGURO DO CARRO (183 O MÊS) | I16: - | J16: =183/4 -> 45.75 | K16: =J16/$D$7 -> 0.010166667
C17: FINANCIAMENTO CARRO (1197,66 O MÊS) | D17: - | E17: =1197.66/4 -> 299.415 | F17: =E17/$D$7 -> 0.066536667 | H17: FINANCIAMENTO CARRO (1197,66 O MÊS) | I17: - | J17: =1197.66/4 -> 299.415 | K17: =J17/$D$7 -> 0.066536667
C18: PEDAGIOS | D18: - | E18: 100 | F18: =E18/$D$7 -> 0.022222222 | H18: PEDAGIOS | I18: - | J18: 100 | K18: =J18/$D$7 -> 0.022222222
C19: MANUTENÇÃO | D19: - | E19: 100 | F19: =E19/$D$7 -> 0.022222222 | H19: MANUTENÇÃO | I19: - | J19: 100 | K19: =J19/$D$7 -> 0.022222222
D21: =SUM(D10:D20) -> 2990 | E21: =SUM(E14:E20) -> 620.915 | F21: =SUM(F10:F20) -> 0.80242556 | I21: =SUM(I10:I20) -> 3450 | J21: =SUM(J14:J20) -> 620.915 | K21: =SUM(K10:K20) -> 0.90464778
C22: TOTAL | D22: =D21+E21 -> 3610.915 | H22: TOTAL | I22: =I21+J21 -> 4070.915
C23: RESULTADO DA SEMANA | D23: =D7-D22 -> 889.085 | F23: =D23/D7 -> 0.19757444 | H23: RESULTADO DA SEMANA | I23: =I7-I22 -> 929.085 | K23: =I23/I7 -> 0.185817
C27: FATURAR NA SEMANA | D27: 5500 | H27: FATURAR NA SEMANA | I27: 6000
C29: GASTOS | D29: VALOR | H29: GASTOS | I29: VALOR
C30: DISPATCHER (RODRIGO) | D30: =D27*0.12 -> 660 | E30: - | F30: =D30/$D$7 -> 0.14666667 | H30: DISPATCHER (RODRIGO) | I30: =I27*0.12 -> 720 | J30: - | K30: =I30/$D$7 -> 0.16
C31: DRIVER (MARCOS) | D31: =D27*0.3 -> 1650 | E31: - | F31: =D31/$D$7 -> 0.36666667 | H31: DRIVER (MARCOS) | I31: =I27*0.3 -> 1800 | J31: - | K31: =I31/$D$7 -> 0.4
C32: COMBUSTIVEL | D32: 1300 | E32: - | F32: =D32/$D$7 -> 0.28888889 | H32: COMBUSTIVEL | I32: 1500 | J32: - | K32: =I32/$D$7 -> 0.33333333
C33: SEGURO CARGA SEMANAL | D33: 250 | E33: - | F33: =D33/$D$7 -> 0.055555556 | H33: SEGURO CARGA SEMANAL | I33: 250 | J33: - | K33: =I33/$D$7 -> 0.055555556
C34: LOG BOOK MAGICA (153 O MÊS) | D34: - | E34: =153/4 -> 38.25 | F34: =E34/$D$7 -> 0.0085 | H34: LOG BOOK MAGICA (153 O MÊS) | I34: - | J34: =153/4 -> 38.25 | K34: =J34/$D$7 -> 0.0085
C35: YARD (150 O MÊS) | D35: - | E35: =150/4 -> 37.5 | F35: =E35/$D$7 -> 0.0083333333 | H35: YARD (150 O MÊS) | I35: - | J35: =150/4 -> 37.5 | K35: =J35/$D$7 -> 0.0083333333
C36: SEGURO DO CARRO (183 O MÊS) | D36: - | E36: =183/4 -> 45.75 | F36: =E36/$D$7 -> 0.010166667 | H36: SEGURO DO CARRO (183 O MÊS) | I36: - | J36: =183/4 -> 45.75 | K36: =J36/$D$7 -> 0.010166667
C37: FINANCIAMENTO CARRO (1197,66 O MÊS) | D37: - | E37: =1197.66/4 -> 299.415 | F37: =E37/$D$7 -> 0.066536667 | H37: FINANCIAMENTO CARRO (1197,66 O MÊS) | I37: - | J37: =1197.66/4 -> 299.415 | K37: =J37/$D$7 -> 0.066536667
C38: PEDAGIOS | D38: - | E38: 100 | F38: =E38/$D$7 -> 0.022222222 | H38: PEDAGIOS | I38: - | J38: 100 | K38: =J38/$D$7 -> 0.022222222
C39: MANUTENÇÃO | D39: - | E39: 100 | F39: =E39/$D$7 -> 0.022222222 | H39: MANUTENÇÃO | I39: - | J39: 100 | K39: =J39/$D$7 -> 0.022222222
D41: =SUM(D30:D40) -> 3860 | E41: =SUM(E34:E40) -> 620.915 | F41: =SUM(F30:F40) -> 0.99575889 | I41: =SUM(I30:I40) -> 4270 | J41: =SUM(J34:J40) -> 620.915 | K41: =SUM(K30:K40) -> 1.08687
C42: TOTAL | D42: =D41+E41 -> 4480.915 | H42: TOTAL | I42: =I41+J41 -> 4890.915
C43: RESULTADO DA SEMANA | D43: =D27-D42 -> 1019.085 | F43: =D43/D27 -> 0.18528818 | H43: RESULTADO DA SEMANA | I43: =I27-I42 -> 1109.085 | K43: =I43/I27 -> 0.1848475
